Workbook

Sheet BOM Additions
A1: BOM Post-Release Addition Tracker | U1: Procurement Use
A2: # | B2: Job No. | C2: Job Description | D2: BOM Release Date | E2: Addition Date | F2: Days After Release | G2: Part No. | H2: Part Description | I2: Qty | J2: Unit Cost (AUD) | K2: Total Cost (AUD) | L2: Reason Code | M2: Requested By | N2: Approved By | O2: Procurement Status | P2: Supplier | Q2: PO Number | R2: Required By | S2: Expected Delivery | T2: Actual Delivery | U2: Delivery Status | V2: Notes
A3: =ROW()-2 | B3: 801254 | C3: Aviation Refueller Mk4 | D3: 46231 | E3: 46239 | F3: =IF(AND(D3<>"",E3<>""),E3-D3,"") | G3: HYD-SEAL-088 | H3: Hydraulic seal kit — actuator arm | I3: 2 | J3: 145 | K3: =IF(AND(I3<>"",J3<>""),I3*J3,"") | L3: Engineering Change | M3: T. Wallace | N3: G. Kalms | O3: Ordered | P3: Hydraforce Pty Ltd | Q3: PO-2026-0412 | R3: 46254 | S3: 46252 | U3: =IF(T3<>"","Received",IF(AND(S3<>"",S3<TODAY()),"⚠ Overdue","On Track")) | V3: Required before cab assembly — flagged by engineering 4/8
A4: =IF(B4<>"",ROW()-2,"") | B4: 801235 | F4: =IF(AND(D4<>"",E4<>""),E4-D4,"") | G4: 10000-10-12 | I4: 1 | J4: 23.89 | K4: =IF(AND(I4<>"",J4<>""),I4*J4,"") | O4: Complete | P4: FROM STOCK | U4: =IF(T4<>"","Received",IF(AND(S4<>"",S4<TODAY()),"⚠ Overdue","On Track"))
A5: =IF(B5<>"",ROW()-2,"") | B5: 801236 | F5: =IF(AND(D5<>"",E5<>""),E5-D5,"") | G5: 10000-10-12 | I5: 1 | J5: 23.89 | K5: =IF(AND(I5<>"",J5<>""),I5*J5,"") | O5: Complete | P5: FROM STOCK | U5: =IF(T5<>"","Received",IF(AND(S5<>"",S5<TODAY()),"⚠ Overdue","On Track"))
A6: =IF(B6<>"",ROW()-2,"") | B6: 801235 | F6: =IF(AND(D6<>"",E6<>""),E6-D6,"") | G6: 10000-10-35 | I6: 2 | J6: 99.24 | K6: =IF(AND(I6<>"",J6<>""),I6*J6,"") | O6: Complete | P6: FROM STOCK | U6: =IF(T6<>"","Received",IF(AND(S6<>"",S6<TODAY()),"⚠ Overdue","On Track"))
A7: =IF(B7<>"",ROW()-2,"") | B7: 801236 | F7: =IF(AND(D7<>"",E7<>""),E7-D7,"") | G7: 10000-10-35 | I7: 2 | J7: 99.24 | K7: =IF(AND(I7<>"",J7<>""),I7*J7,"") | O7: Complete | P7: FROM STOCK | U7: =IF(T7<>"","Received",IF(AND(S7<>"",S7<TODAY()),"⚠ Overdue","On Track"))
A8: =IF(B8<>"",ROW()-2,"") | B8: 801235 | F8: =IF(AND(D8<>"",E8<>""),E8-D8,"") | G8: 10000-10-37 | I8: 1 | J8: 24 | K8: =IF(AND(I8<>"",J8<>""),I8*J8,"") | O8: Complete | P8: FROM STOCK | U8: =IF(T8<>"","Received",IF(AND(S8<>"",S8<TODAY()),"⚠ Overdue","On Track"))
A9: =IF(B9<>"",ROW()-2,"") | B9: 801236 | F9: =IF(AND(D9<>"",E9<>""),E9-D9,"") | G9: 10000-10-37 | I9: 1 | J9: 24 | K9: =IF(AND(I9<>"",J9<>""),I9*J9,"") | O9: Complete | P9: FROM STOCK | U9: =IF(T9<>"","Received",IF(AND(S9<>"",S9<TODAY()),"⚠ Overdue","On Track"))
A10: =IF(B10<>"",ROW()-2,"") | B10: 801235 | F10: =IF(AND(D10<>"",E10<>""),E10-D10,"") | G10: 10000-10-67 | I10: 1 | J10: 4.84 | K10: =IF(AND(I10<>"",J10<>""),I10*J10,"") | O10: Complete | P10: FROM STOCK | U10: =IF(T10<>"","Received",IF(AND(S10<>"",S10<TODAY()),"⚠ Overdue","On Track"))
A11: =IF(B11<>"",ROW()-2,"") | B11: 801236 | F11: =IF(AND(D11<>"",E11<>""),E11-D11,"") | G11: 10000-10-67 | I11: 1 | J11: 4.84 | K11: =IF(AND(I11<>"",J11<>""),I11*J11,"") | O11: Complete | P11: FROM STOCK | U11: =IF(T11<>"","Received",IF(AND(S11<>"",S11<TODAY()),"⚠ Overdue","On Track"))
A12: =IF(B12<>"",ROW()-2,"") | B12: 801216 | F12: =IF(AND(D12<>"",E12<>""),E12-D12,"") | G12: 25699-FLOW | H12: FLOW LABEL | I12: 1 | J12: 71.5 | K12: =IF(AND(I12<>"",J12<>""),I12*J12,"") | M12: Sri | O12: Ordered | P12: Niddrie | Q12: PO119955 | U12: =IF(T12<>"","Received",IF(AND(S12<>"",S12<TODAY()),"⚠ Overdue","On Track"))
A13: =IF(B13<>"",ROW()-2,"") | B13: 801217 | F13: =IF(AND(D13<>"",E13<>""),E13-D13,"") | G13: 25699-FLOW | H13: FLOW LABEL | I13: 1 | J13: 71.5 | K13: =IF(AND(I13<>"",J13<>""),I13*J13,"") | M13: Sri | O13: Ordered | P13: Niddrie | Q13: PO119955 | U13: =IF(T13<>"","Received",IF(AND(S13<>"",S13<TODAY()),"⚠ Overdue","On Track"))
A14: =IF(B14<>"",ROW()-2,"") | B14: 801218 | F14: =IF(AND(D14<>"",E14<>""),E14-D14,"") | G14: 25699-FLOW | H14: FLOW LABEL | I14: 1 | J14: 71.5 | K14: =IF(AND(I14<>"",J14<>""),I14*J14,"") | M14: Sri | O14: Ordered | P14: Niddrie | Q14: PO119955 | U14: =IF(T14<>"","Received",IF(AND(S14<>"",S14<TODAY()),"⚠ Overdue","On Track"))
A15: =IF(B15<>"",ROW()-2,"") | B15: 801219 | F15: =IF(AND(D15<>"",E15<>""),E15-D15,"") | G15: 25699-FLOW | H15: FLOW LABEL | I15: 1 | J15: 71.5 | K15: =IF(AND(I15<>"",J15<>""),I15*J15,"") | M15: Sri | O15: Ordered | P15: Niddrie | Q15: PO119955 | U15: =IF(T15<>"","Received",IF(AND(S15<>"",S15<TODAY()),"⚠ Overdue","On Track"))
A16: =IF(B16<>"",ROW()-2,"") | B16: 801237 | F16: =IF(AND(D16<>"",E16<>""),E16-D16,"") | G16: 25699-FLOW | H16: FLOW LABEL | I16: 1 | J16: 71.5 | K16: =IF(AND(I16<>"",J16<>""),I16*J16,"") | M16: Sri | O16: Ordered | P16: Niddrie | Q16: PO119955 | U16: =IF(T16<>"","Received",IF(AND(S16<>"",S16<TODAY()),"⚠ Overdue","On Track"))
A17: =IF(B17<>"",ROW()-2,"") | B17: 801238 | F17: =IF(AND(D17<>"",E17<>""),E17-D17,"") | G17: 25699-FLOW | H17: FLOW LABEL | I17: 1 | J17: 71.5 | K17: =IF(AND(I17<>"",J17<>""),I17*J17,"") | M17: Sri | O17: Ordered | P17: Niddrie | Q17: PO119955 | U17: =IF(T17<>"","Received",IF(AND(S17<>"",S17<TODAY()),"⚠ Overdue","On Track"))
A18: =IF(B18<>"",ROW()-2,"") | B18: 801239 | F18: =IF(AND(D18<>"",E18<>""),E18-D18,"") | G18: 25699-FLOW | H18: FLOW LABEL | I18: 1 | J18: 71.5 | K18: =IF(AND(I18<>"",J18<>""),I18*J18,"") | M18: Sri | O18: Ordered | P18: Niddrie | Q18: PO119955 | U18: =IF(T18<>"","Received",IF(AND(S18<>"",S18<TODAY()),"⚠ Overdue","On Track"))
A19: =IF(B19<>"",ROW()-2,"") | B19: 801240 | F19: =IF(AND(D19<>"",E19<>""),E19-D19,"") | G19: 25699-FLOW | H19: FLOW LABEL | I19: 1 | J19: 71.5 | K19: =IF(AND(I19<>"",J19<>""),I19*J19,"") | M19: Sri | O19: Ordered | P19: Niddrie | Q19: PO119955 | U19: =IF(T19<>"","Received",IF(AND(S19<>"",S19<TODAY()),"⚠ Overdue","On Track"))
A20: =IF(B20<>"",ROW()-2,"") | B20: 801241 | F20: =IF(AND(D20<>"",E20<>""),E20-D20,"") | G20: 25699-FLOW | H20: FLOW LABEL | I20: 1 | J20: 71.5 | K20: =IF(AND(I20<>"",J20<>""),I20*J20,"") | M20: Sri | O20: Ordered | P20: Niddrie | Q20: PO119955 | U20: =IF(T20<>"","Received",IF(AND(S20<>"",S20<TODAY()),"⚠ Overdue","On Track"))
A21: =IF(B21<>"",ROW()-2,"") | B21: 801241 | F21: =IF(AND(D21<>"",E21<>""),E21-D21,"") | G21: 3000-03-05 | H21: DEADMAN HANDLE TRAY LARGE | I21: 1 | J21: 118.72 | K21: =IF(AND(I21<>"",J21<>""),I21*J21,"") | O21: Ordered | P21: HUNT | Q21: PO119947 | U21: =IF(T21<>"","Received",IF(AND(S21<>"",S21<TODAY()),"⚠ Overdue","On Track"))
A22: =IF(B22<>"",ROW()-2,"") | B22: 801241 | F22: =IF(AND(D22<>"",E22<>""),E22-D22,"") | G22: 3000-32-161 | H22: BRACKET VALVE OPERATION LABEL FLAT 4" MANNTEK | I22: 1 | J22: 6.8 | K22: =IF(AND(I22<>"",J22<>""),I22*J22,"") | O22: Ordered | P22: HUNT | Q22: PO119948 | U22: =IF(T22<>"","Received",IF(AND(S22<>"",S22<TODAY()),"⚠ Overdue","On Track"))
A23: =IF(B23<>"",ROW()-2,"") | B23: 801241 | F23: =IF(AND(D23<>"",E23<>""),E23-D23,"") | G23: 3000-32-55 | H23: VALVE OPERATION LABEL BRACKET | I23: 3 | J23: 14.95 | K23: =IF(AND(I23<>"",J23<>""),I23*J23,"") | O23: Ordered | P23: HUNT | Q23: PO119949 | U23: =IF(T23<>"","Received",IF(AND(S23<>"",S23<TODAY()),"⚠ Overdue","On Track"))
A24: =IF(B24<>"",ROW()-2,"") | B24: 801216 | F24: =IF(AND(D24<>"",E24<>""),E24-D24,"") | G24: 4600-06-18 | H24: OPW295 OVERWING NOZZLE INTERLOCK BRACKET | I24: 1 | J24: 148.64 | K24: =IF(AND(I24<>"",J24<>""),I24*J24,"") | O24: Ordered | P24: HUNT | Q24: PO119947 | U24: =IF(T24<>"","Received",IF(AND(S24<>"",S24<TODAY()),"⚠ Overdue","On Track"))
A25: =IF(B25<>"",ROW()-2,"") | B25: 801217 | F25: =IF(AND(D25<>"",E25<>""),E25-D25,"") | G25: 4600-06-18 | H25: OPW295 OVERWING NOZZLE INTERLOCK BRACKET | I25: 1 | J25: 148.64 | K25: =IF(AND(I25<>"",J25<>""),I25*J25,"") | O25: Ordered | P25: HUNT | Q25: PO119948 | U25: =IF(T25<>"","Received",IF(AND(S25<>"",S25<TODAY()),"⚠ Overdue","On Track"))
A26: =IF(B26<>"",ROW()-2,"") | B26: 801218 | F26: =IF(AND(D26<>"",E26<>""),E26-D26,"") | G26: 4600-06-18 | H26: OPW295 OVERWING NOZZLE INTERLOCK BRACKET | I26: 1 | J26: 148.64 | K26: =IF(AND(I26<>"",J26<>""),I26*J26,"") | O26: Ordered | P26: HUNT | Q26: PO119949 | U26: =IF(T26<>"","Received",IF(AND(S26<>"",S26<TODAY()),"⚠ Overdue","On Track"))
A27: =IF(B27<>"",ROW()-2,"") | B27: 801219 | F27: =IF(AND(D27<>"",E27<>""),E27-D27,"") | G27: 4600-06-18 | H27: OPW295 OVERWING NOZZLE INTERLOCK BRACKET | I27: 1 | J27: 148.64 | K27: =IF(AND(I27<>"",J27<>""),I27*J27,"") | O27: Ordered | P27: HUNT | Q27: PO119950 | U27: =IF(T27<>"","Received",IF(AND(S27<>"",S27<TODAY()),"⚠ Overdue","On Track"))
A28: =IF(B28<>"",ROW()-2,"") | B28: 801237 | F28: =IF(AND(D28<>"",E28<>""),E28-D28,"") | G28: 4600-06-18 | H28: OPW295 OVERWING NOZZLE INTERLOCK BRACKET | I28: 1 | J28: 148.64 | K28: =IF(AND(I28<>"",J28<>""),I28*J28,"") | O28: Ordered | P28: HUNT | Q28: PO119951 | U28: =IF(T28<>"","Received",IF(AND(S28<>"",S28<TODAY()),"⚠ Overdue","On Track"))
A29: =IF(B29<>"",ROW()-2,"") | B29: 801238 | F29: =IF(AND(D29<>"",E29<>""),E29-D29,"") | G29: 4600-06-18 | H29: OPW295 OVERWING NOZZLE INTERLOCK BRACKET | I29: 1 | J29: 148.64 | K29: =IF(AND(I29<>"",J29<>""),I29*J29,"") | O29: Ordered | P29: HUNT | Q29: PO119952 | U29: =IF(T29<>"","Received",IF(AND(S29<>"",S29<TODAY()),"⚠ Overdue","On Track"))
A30: =IF(B30<>"",ROW()-2,"") | B30: 801239 | F30: =IF(AND(D30<>"",E30<>""),E30-D30,"") | G30: 4600-06-18 | H30: OPW295 OVERWING NOZZLE INTERLOCK BRACKET | I30: 1 | J30: 148.64 | K30: =IF(AND(I30<>"",J30<>""),I30*J30,"") | O30: Ordered | P30: HUNT | Q30: PO119953 | U30: =IF(T30<>"","Received",IF(AND(S30<>"",S30<TODAY()),"⚠ Overdue","On Track"))
A31: =IF(B31<>"",ROW()-2,"") | B31: 801240 | F31: =IF(AND(D31<>"",E31<>""),E31-D31,"") | G31: 4600-06-18 | H31: OPW295 OVERWING NOZZLE INTERLOCK BRACKET | I31: 1 | J31: 148.64 | K31: =IF(AND(I31<>"",J31<>""),I31*J31,"") | O31: Ordered | P31: HUNT | Q31: PO119954 | U31: =IF(T31<>"","Received",IF(AND(S31<>"",S31<TODAY()),"⚠ Overdue","On Track"))
A32: =IF(B32<>"",ROW()-2,"") | B32: 801235 | F32: =IF(AND(D32<>"",E32<>""),E32-D32,"") | G32: 50700100086 | H32: GASKET ISO 7707 4 HOLE DIAM80 10000-10-103 | I32: 1 | J32: 2.1 | K32: =IF(AND(I32<>"",J32<>""),I32*J32,"") | O32: Ordered | P32: OMFB | Q32: PO120110 | U32: =IF(T32<>"","Received",IF(AND(S32<>"",S32<TODAY()),"⚠ Overdue","On Track"))
... A34: =IF(B34<>"",ROW()-2,"") | B34: 801267 | F34: =IF(AND(D34<>"",E34<>""),E34-D34,"") | G34: 6000-08-63 | H34: LOGO PANEL : SWIVEL REEL LADDER STOWAGE | I34: 1 | J34: 172.86 | K34: =IF(AND(I34<>"",J34<>""),I34*J34,"") | O34: Ordered | P34: HUNT | Q34: PO120112 | U34: =IF(T34<>"","Received",IF(AND(S34<>"",S34<TODAY()),"⚠ Overdue","On Track"))
A35: =IF(B35<>"",ROW()-2,"") | B35: 801269 | F35: =IF(AND(D35<>"",E35<>""),E35-D35,"") | G35: 6020-02-19 | H35: DOUBLE SHEAR LINK PLT-ZP BLUE | I35: 1 | J35: 24.9 | K35: =IF(AND(I35<>"",J35<>""),I35*J35,"") | M35: saurabh | O35: Ordered | P35: HUNT | Q35: PO120254 | U35: =IF(T35<>"","Received",IF(AND(S35<>"",S35<TODAY()),"⚠ Overdue","On Track"))
A36: =IF(B36<>"",ROW()-2,"") | B36: 801270 | F36: =IF(AND(D36<>"",E36<>""),E36-D36,"") | G36: 6020-02-19 | H36: DOUBLE SHEAR LINK PLT-ZP BLUE | I36: 1 | J36: 24.9 | K36: =IF(AND(I36<>"",J36<>""),I36*J36,"") | O36: Ordered | P36: HUNT | Q36: PO120255 | U36: =IF(T36<>"","Received",IF(AND(S36<>"",S36<TODAY()),"⚠ Overdue","On Track"))
A37: =IF(B37<>"",ROW()-2,"") | B37: 801235 | F37: =IF(AND(D37<>"",E37<>""),E37-D37,"") | G37: 7000-06-138 | H37: CONTROL PANEL LABEL | I37: 1 | J37: 275 | K37: =IF(AND(I37<>"",J37<>""),I37*J37,"") | O37: Ordered | P37: EMTAN | Q37: PO119240 | U37: =IF(T37<>"","Received",IF(AND(S37<>"",S37<TODAY()),"⚠ Overdue","On Track"))
A38: =IF(B38<>"",ROW()-2,"") | B38: 801236 | F38: =IF(AND(D38<>"",E38<>""),E38-D38,"") | G38: 7000-06-138 | H38: CONTROL PANEL LABEL | I38: 1 | J38: 275 | K38: =IF(AND(I38<>"",J38<>""),I38*J38,"") | O38: Ordered | P38: EMTAN | Q38: PO119240 | U38: =IF(T38<>"","Received",IF(AND(S38<>"",S38<TODAY()),"⚠ Overdue","On Track"))
A39: =IF(B39<>"",ROW()-2,"") | B39: 801281 | F39: =IF(AND(D39<>"",E39<>""),E39-D39,"") | G39: 7000-29-07 | H39: BRACKET DB MOUNT TO CONTROL PANEL | I39: 1 | K39: =IF(AND(I39<>"",J39<>""),I39*J39,"") | M39: saurabh | O39: Ordered | P39: HUNT | Q39: PO12055 | U39: =IF(T39<>"","Received",IF(AND(S39<>"",S39<TODAY()),"⚠ Overdue","On Track"))
A40: =IF(B40<>"",ROW()-2,"") | B40: 801281 | F40: =IF(AND(D40<>"",E40<>""),E40-D40,"") | G40: 7000-29-08 | H40: BRACKET SIGN PANEL DB COVER | I40: 1 | K40: =IF(AND(I40<>"",J40<>""),I40*J40,"") | M40: saurabh | O40: Ordered | P40: HUNT | Q40: PO12055 | U40: =IF(T40<>"","Received",IF(AND(S40<>"",S40<TODAY()),"⚠ Overdue","On Track"))
A41: =IF(B41<>"",ROW()-2,"") | B41: 801281 | F41: =IF(AND(D41<>"",E41<>""),E41-D41,"") | G41: 7000-29-09 | H41: BRACKET DB MOUNT | I41: 1 | K41: =IF(AND(I41<>"",J41<>""),I41*J41,"") | M41: saurabh | O41: Ordered | P41: HUNT | Q41: PO12055 | U41: =IF(T41<>"","Received",IF(AND(S41<>"",S41<TODAY()),"⚠ Overdue","On Track"))
...

Sheet Job Summary
A1: Job Summary — BOM Post-Release Additions | H1: Auto-calculated
A2: Job No. | B2: Job Description | C2: BOM Release Date | D2: # Additions | E2: Total Cost Impact | F2: Items Pending | G2: Items Ordered | H2: Items Received | I2: Notes
A3: 801253 | B3: Aviation Refueller — Unit A | C3: 46217 | D3: =COUNTIF('BOM Additions'!B$4:B$153,A3) | E3: =SUMIF('BOM Additions'!B$4:B$153,A3,'BOM Additions'!K$4:K$153) | F3: =COUNTIFS('BOM Additions'!B$4:B$153,A3,'BOM Additions'!O$4:O$153,"Pending") | G3: =COUNTIFS('BOM Additions'!B$4:B$153,A3,'BOM Additions'!O$4:O$153,"PO Raised")+COUNTIFS('BOM Additions'!B$4:B$153,A3,'BOM Additions'!O$4:O$153,"Ordered") | H3: =COUNTIFS('BOM Additions'!B$4:B$153,A3,'BOM Additions'!O$4:O$153,"Complete")
A4: 801254 | B4: Aviation Refueller Mk4 | C4: 46231 | D4: =COUNTIF('BOM Additions'!B$4:B$153,A4) | E4: =SUMIF('BOM Additions'!B$4:B$153,A4,'BOM Additions'!K$4:K$153) | F4: =COUNTIFS('BOM Additions'!B$4:B$153,A4,'BOM Additions'!O$4:O$153,"Pending") | G4: =COUNTIFS('BOM Additions'!B$4:B$153,A4,'BOM Additions'!O$4:O$153,"PO Raised")+COUNTIFS('BOM Additions'!B$4:B$153,A4,'BOM Additions'!O$4:O$153,"Ordered") | H4: =COUNTIFS('BOM Additions'!B$4:B$153,A4,'BOM Additions'!O$4:O$153,"Complete")
A5: 801256 | B5: Fuel Tanker — Rear Config | C5: 46224 | D5: =COUNTIF('BOM Additions'!B$4:B$153,A5) | E5: =SUMIF('BOM Additions'!B$4:B$153,A5,'BOM Additions'!K$4:K$153) | F5: =COUNTIFS('BOM Additions'!B$4:B$153,A5,'BOM Additions'!O$4:O$153,"Pending") | G5: =COUNTIFS('BOM Additions'!B$4:B$153,A5,'BOM Additions'!O$4:O$153,"PO Raised")+COUNTIFS('BOM Additions'!B$4:B$153,A5,'BOM Additions'!O$4:O$153,"Ordered") | H5: =COUNTIFS('BOM Additions'!B$4:B$153,A5,'BOM Additions'!O$4:O$153,"Complete")
A6: 801257 | B6: Fuel Tanker — Std Config | C6: 46224 | D6: =COUNTIF('BOM Additions'!B$4:B$153,A6) | E6: =SUMIF('BOM Additions'!B$4:B$153,A6,'BOM Additions'!K$4:K$153) | F6: =COUNTIFS('BOM Additions'!B$4:B$153,A6,'BOM Additions'!O$4:O$153,"Pending") | G6: =COUNTIFS('BOM Additions'!B$4:B$153,A6,'BOM Additions'!O$4:O$153,"PO Raised")+COUNTIFS('BOM Additions'!B$4:B$153,A6,'BOM Additions'!O$4:O$153,"Ordered") | H6: =COUNTIFS('BOM Additions'!B$4:B$153,A6,'BOM Additions'!O$4:O$153,"Complete")
A7: 801258 | B7: Aviation Refueller — Unit B | C7: 46231 | D7: =COUNTIF('BOM Additions'!B$4:B$153,A7) | E7: =SUMIF('BOM Additions'!B$4:B$153,A7,'BOM Additions'!K$4:K$153) | F7: =COUNTIFS('BOM Additions'!B$4:B$153,A7,'BOM Additions'!O$4:O$153,"Pending") | G7: =COUNTIFS('BOM Additions'!B$4:B$153,A7,'BOM Additions'!O$4:O$153,"PO Raised")+COUNTIFS('BOM Additions'!B$4:B$153,A7,'BOM Additions'!O$4:O$153,"Ordered") | H7: =COUNTIFS('BOM Additions'!B$4:B$153,A7,'BOM Additions'!O$4:O$153,"Complete")
A8: 801215 | D8: =COUNTIF('BOM Additions'!B$4:B$153,A8) | E8: =SUMIF('BOM Additions'!B$4:B$153,A8,'BOM Additions'!K$4:K$153) | F8: =COUNTIFS('BOM Additions'!B$4:B$153,A8,'BOM Additions'!O$4:O$153,"Pending") | G8: =COUNTIFS('BOM Additions'!B$4:B$153,A8,'BOM Additions'!O$4:O$153,"PO Raised")+COUNTIFS('BOM Additions'!B$4:B$153,A8,'BOM Additions'!O$4:O$153,"Ordered") | H8: =COUNTIFS('BOM Additions'!B$4:B$153,A8,'BOM Additions'!O$4:O$153,"Complete")
A9: 801216 | D9: =COUNTIF('BOM Additions'!B$4:B$153,A9) | E9: =SUMIF('BOM Additions'!B$4:B$153,A9,'BOM Additions'!K$4:K$153) | F9: =COUNTIFS('BOM Additions'!B$4:B$153,A9,'BOM Additions'!O$4:O$153,"Pending") | G9: =COUNTIFS('BOM Additions'!B$4:B$153,A9,'BOM Additions'!O$4:O$153,"PO Raised")+COUNTIFS('BOM Additions'!B$4:B$153,A9,'BOM Additions'!O$4:O$153,"Ordered") | H9: =COUNTIFS('BOM Additions'!B$4:B$153,A9,'BOM Additions'!O$4:O$153,"Complete")
A10: 801217 | D10: =COUNTIF('BOM Additions'!B$4:B$153,A10) | E10: =SUMIF('BOM Additions'!B$4:B$153,A10,'BOM Additions'!K$4:K$153) | F10: =COUNTIFS('BOM Additions'!B$4:B$153,A10,'BOM Additions'!O$4:O$153,"Pending") | G10: =COUNTIFS('BOM Additions'!B$4:B$153,A10,'BOM Additions'!O$4:O$153,"PO Raised")+COUNTIFS('BOM Additions'!B$4:B$153,A10,'BOM Additions'!O$4:O$153,"Ordered") | H10: =COUNTIFS('BOM Additions'!B$4:B$153,A10,'BOM Additions'!O$4:O$153,"Complete")
A11: 801218 | D11: =COUNTIF('BOM Additions'!B$4:B$153,A11) | E11: =SUMIF('BOM Additions'!B$4:B$153,A11,'BOM Additions'!K$4:K$153) | F11: =COUNTIFS('BOM Additions'!B$4:B$153,A11,'BOM Additions'!O$4:O$153,"Pending") | G11: =COUNTIFS('BOM Additions'!B$4:B$153,A11,'BOM Additions'!O$4:O$153,"PO Raised")+COUNTIFS('BOM Additions'!B$4:B$153,A11,'BOM Additions'!O$4:O$153,"Ordered") | H11: =COUNTIFS('BOM Additions'!B$4:B$153,A11,'BOM Additions'!O$4:O$153,"Complete")
A12: 801219 | D12: =COUNTIF('BOM Additions'!B$4:B$153,A12) | E12: =SUMIF('BOM Additions'!B$4:B$153,A12,'BOM Additions'!K$4:K$153) | F12: =COUNTIFS('BOM Additions'!B$4:B$153,A12,'BOM Additions'!O$4:O$153,"Pending") | G12: =COUNTIFS('BOM Additions'!B$4:B$153,A12,'BOM Additions'!O$4:O$153,"PO Raised")+COUNTIFS('BOM Additions'!B$4:B$153,A12,'BOM Additions'!O$4:O$153,"Ordered") | H12: =COUNTIFS('BOM Additions'!B$4:B$153,A12,'BOM Additions'!O$4:O$153,"Complete")
A13: 801235 | D13: =COUNTIF('BOM Additions'!B$4:B$153,A13) | E13: =SUMIF('BOM Additions'!B$4:B$153,A13,'BOM Additions'!K$4:K$153) | F13: =COUNTIFS('BOM Additions'!B$4:B$153,A13,'BOM Additions'!O$4:O$153,"Pending") | G13: =COUNTIFS('BOM Additions'!B$4:B$153,A13,'BOM Additions'!O$4:O$153,"PO Raised")+COUNTIFS('BOM Additions'!B$4:B$153,A13,'BOM Additions'!O$4:O$153,"Ordered") | H13: =COUNTIFS('BOM Additions'!B$4:B$153,A13,'BOM Additions'!O$4:O$153,"Complete")
A14: 801236 | D14: =COUNTIF('BOM Additions'!B$4:B$153,A14) | E14: =SUMIF('BOM Additions'!B$4:B$153,A14,'BOM Additions'!K$4:K$153) | F14: =COUNTIFS('BOM Additions'!B$4:B$153,A14,'BOM Additions'!O$4:O$153,"Pending") | G14: =COUNTIFS('BOM Additions'!B$4:B$153,A14,'BOM Additions'!O$4:O$153,"PO Raised")+COUNTIFS('BOM Additions'!B$4:B$153,A14,'BOM Additions'!O$4:O$153,"Ordered") | H14: =COUNTIFS('BOM Additions'!B$4:B$153,A14,'BOM Additions'!O$4:O$153,"Complete")
A15: 801237 | D15: =COUNTIF('BOM Additions'!B$4:B$153,A15) | E15: =SUMIF('BOM Additions'!B$4:B$153,A15,'BOM Additions'!K$4:K$153) | F15: =COUNTIFS('BOM Additions'!B$4:B$153,A15,'BOM Additions'!O$4:O$153,"Pending") | G15: =COUNTIFS('BOM Additions'!B$4:B$153,A15,'BOM Additions'!O$4:O$153,"PO Raised")+COUNTIFS('BOM Additions'!B$4:B$153,A15,'BOM Additions'!O$4:O$153,"Ordered") | H15: =COUNTIFS('BOM Additions'!B$4:B$153,A15,'BOM Additions'!O$4:O$153,"Complete")
A16: 801238 | D16: =COUNTIF('BOM Additions'!B$4:B$153,A16) | E16: =SUMIF('BOM Additions'!B$4:B$153,A16,'BOM Additions'!K$4:K$153) | F16: =COUNTIFS('BOM Additions'!B$4:B$153,A16,'BOM Additions'!O$4:O$153,"Pending") | G16: =COUNTIFS('BOM Additions'!B$4:B$153,A16,'BOM Additions'!O$4:O$153,"PO Raised")+COUNTIFS('BOM Additions'!B$4:B$153,A16,'BOM Additions'!O$4:O$153,"Ordered") | H16: =COUNTIFS('BOM Additions'!B$4:B$153,A16,'BOM Additions'!O$4:O$153,"Complete")
A17: 801239 | D17: =COUNTIF('BOM Additions'!B$4:B$153,A17) | E17: =SUMIF('BOM Additions'!B$4:B$153,A17,'BOM Additions'!K$4:K$153) | F17: =COUNTIFS('BOM Additions'!B$4:B$153,A17,'BOM Additions'!O$4:O$153,"Pending") | G17: =COUNTIFS('BOM Additions'!B$4:B$153,A17,'BOM Additions'!O$4:O$153,"PO Raised")+COUNTIFS('BOM Additions'!B$4:B$153,A17,'BOM Additions'!O$4:O$153,"Ordered") | H17: =COUNTIFS('BOM Additions'!B$4:B$153,A17,'BOM Additions'!O$4:O$153,"Complete")
A18: 801240 | D18: =COUNTIF('BOM Additions'!B$4:B$153,A18) | E18: =SUMIF('BOM Additions'!B$4:B$153,A18,'BOM Additions'!K$4:K$153) | F18: =COUNTIFS('BOM Additions'!B$4:B$153,A18,'BOM Additions'!O$4:O$153,"Pending") | G18: =COUNTIFS('BOM Additions'!B$4:B$153,A18,'BOM Additions'!O$4:O$153,"PO Raised")+COUNTIFS('BOM Additions'!B$4:B$153,A18,'BOM Additions'!O$4:O$153,"Ordered") | H18: =COUNTIFS('BOM Additions'!B$4:B$153,A18,'BOM Additions'!O$4:O$153,"Complete")
A19: 801241 | D19: =COUNTIF('BOM Additions'!B$4:B$153,A19) | E19: =SUMIF('BOM Additions'!B$4:B$153,A19,'BOM Additions'!K$4:K$153) | F19: =COUNTIFS('BOM Additions'!B$4:B$153,A19,'BOM Additions'!O$4:O$153,"Pending") | G19: =COUNTIFS('BOM Additions'!B$4:B$153,A19,'BOM Additions'!O$4:O$153,"PO Raised")+COUNTIFS('BOM Additions'!B$4:B$153,A19,'BOM Additions'!O$4:O$153,"Ordered") | H19: =COUNTIFS('BOM Additions'!B$4:B$153,A19,'BOM Additions'!O$4:O$153,"Complete")
... A27: 801281 | D27: =COUNTIF('BOM Additions'!B$4:B$153,A27) | E27: =SUMIF('BOM Additions'!B$4:B$153,A27,'BOM Additions'!K$4:K$153) | F27: =COUNTIFS('BOM Additions'!B$4:B$153,A27,'BOM Additions'!O$4:O$153,"Pending") | G27: =COUNTIFS('BOM Additions'!B$4:B$153,A27,'BOM Additions'!O$4:O$153,"PO Raised")+COUNTIFS('BOM Additions'!B$4:B$153,A27,'BOM Additions'!O$4:O$153,"Ordered") | H27: =COUNTIFS('BOM Additions'!B$4:B$153,A27,'BOM Additions'!O$4:O$153,"Complete")

Sheet Reference
A1: Reason Code | B1: Procurement Status | C1: Why was this part added after BOM release?
A2: Engineering Change | B2: Pending | C2: Design was updated after BOM issued
A3: Customer Request | B3: PO Raised | C3: Customer requested additional item
A4: Error / Omission | B4: Ordered | C4: Part missing from original BOM
A5: Design Update | B5: Partial Receipt | C5: Internal design revision
A6: Substitution | B6: Complete | C6: Original part replaced with equivalent
A7: Additional Scope | B7: Cancelled | C7: Scope increased after release
A8: Other | C8: Document reason in Notes column

Sheet Monthly Trend
A1: Monthly BOM Additions — Value & Quantity | E1: Auto from BOM Additions
A2: Month | B2: Month Start | C2: # Additions | D2: Total Value (AUD) | E2: Avg Value / Add. | F2: Running Total AUD
A3: Jan-26 | B3: 46023 | C3: =SUMPRODUCT((YEAR('BOM Additions'!$E$3:$E$53)=YEAR($B3))*(MONTH('BOM Additions'!$E$3:$E$53)=MONTH($B3))*ISNUMBER('BOM Additions'!$E$3:$E$53)*1) | D3: =SUMPRODUCT((YEAR('BOM Additions'!$E$3:$E$53)=YEAR($B3))*(MONTH('BOM Additions'!$E$3:$E$53)=MONTH($B3))*ISNUMBER('BOM Additions'!$E$3:$E$53)*('BOM Additions'!$K$3:$K$53)) | E3: =IF(C3=0,"",D3/C3) | F3: =D3
A4: Feb-26 | B4: 46054 | C4: =SUMPRODUCT((YEAR('BOM Additions'!$E$3:$E$53)=YEAR($B4))*(MONTH('BOM Additions'!$E$3:$E$53)=MONTH($B4))*ISNUMBER('BOM Additions'!$E$3:$E$53)*1) | D4: =SUMPRODUCT((YEAR('BOM Additions'!$E$3:$E$53)=YEAR($B4))*(MONTH('BOM Additions'!$E$3:$E$53)=MONTH($B4))*ISNUMBER('BOM Additions'!$E$3:$E$53)*('BOM Additions'!$K$3:$K$53)) | E4: =IF(C4=0,"",D4/C4) | F4: =F3+D4
A5: Mar-26 | B5: 46082 | C5: =SUMPRODUCT((YEAR('BOM Additions'!$E$3:$E$53)=YEAR($B5))*(MONTH('BOM Additions'!$E$3:$E$53)=MONTH($B5))*ISNUMBER('BOM Additions'!$E$3:$E$53)*1) | D5: =SUMPRODUCT((YEAR('BOM Additions'!$E$3:$E$53)=YEAR($B5))*(MONTH('BOM Additions'!$E$3:$E$53)=MONTH($B5))*ISNUMBER('BOM Additions'!$E$3:$E$53)*('BOM Additions'!$K$3:$K$53)) | E5: =IF(C5=0,"",D5/C5) | F5: =F4+D5
A6: Apr-26 | B6: 46113 | C6: =SUMPRODUCT((YEAR('BOM Additions'!$E$3:$E$53)=YEAR($B6))*(MONTH('BOM Additions'!$E$3:$E$53)=MONTH($B6))*ISNUMBER('BOM Additions'!$E$3:$E$53)*1) | D6: =SUMPRODUCT((YEAR('BOM Additions'!$E$3:$E$53)=YEAR($B6))*(MONTH('BOM Additions'!$E$3:$E$53)=MONTH($B6))*ISNUMBER('BOM Additions'!$E$3:$E$53)*('BOM Additions'!$K$3:$K$53)) | E6: =IF(C6=0,"",D6/C6) | F6: =F5+D6
A7: May-26 | B7: 46143 | C7: =SUMPRODUCT((YEAR('BOM Additions'!$E$3:$E$53)=YEAR($B7))*(MONTH('BOM Additions'!$E$3:$E$53)=MONTH($B7))*ISNUMBER('BOM Additions'!$E$3:$E$53)*1) | D7: =SUMPRODUCT((YEAR('BOM Additions'!$E$3:$E$53)=YEAR($B7))*(MONTH('BOM Additions'!$E$3:$E$53)=MONTH($B7))*ISNUMBER('BOM Additions'!$E$3:$E$53)*('BOM Additions'!$K$3:$K$53)) | E7: =IF(C7=0,"",D7/C7) | F7: =F6+D7
A8: Jun-26 | B8: 46174 | C8: =SUMPRODUCT((YEAR('BOM Additions'!$E$3:$E$53)=YEAR($B8))*(MONTH('BOM Additions'!$E$3:$E$53)=MONTH($B8))*ISNUMBER('BOM Additions'!$E$3:$E$53)*1) | D8: =SUMPRODUCT((YEAR('BOM Additions'!$E$3:$E$53)=YEAR($B8))*(MONTH('BOM Additions'!$E$3:$E$53)=MONTH($B8))*ISNUMBER('BOM Additions'!$E$3:$E$53)*('BOM Additions'!$K$3:$K$53)) | E8: =IF(C8=0,"",D8/C8) | F8: =F7+D8
A9: Jul-26 | B9: 46204 | C9: =SUMPRODUCT((YEAR('BOM Additions'!$E$3:$E$53)=YEAR($B9))*(MONTH('BOM Additions'!$E$3:$E$53)=MONTH($B9))*ISNUMBER('BOM Additions'!$E$3:$E$53)*1) | D9: =SUMPRODUCT((YEAR('BOM Additions'!$E$3:$E$53)=YEAR($B9))*(MONTH('BOM Additions'!$E$3:$E$53)=MONTH($B9))*ISNUMBER('BOM Additions'!$E$3:$E$53)*('BOM Additions'!$K$3:$K$53)) | E9: =IF(C9=0,"",D9/C9) | F9: =F8+D9
A10: Aug-26 | B10: 46235 | C10: =SUMPRODUCT((YEAR('BOM Additions'!$E$3:$E$53)=YEAR($B10))*(MONTH('BOM Additions'!$E$3:$E$53)=MONTH($B10))*ISNUMBER('BOM Additions'!$E$3:$E$53)*1) | D10: =SUMPRODUCT((YEAR('BOM Additions'!$E$3:$E$53)=YEAR($B10))*(MONTH('BOM Additions'!$E$3:$E$53)=MONTH($B10))*ISNUMBER('BOM Additions'!$E$3:$E$53)*('BOM Additions'!$K$3:$K$53)) | E10: =IF(C10=0,"",D10/C10) | F10: =F9+D10
A11: Sep-26 | B11: 46266 | C11: =SUMPRODUCT((YEAR('BOM Additions'!$E$3:$E$53)=YEAR($B11))*(MONTH('BOM Additions'!$E$3:$E$53)=MONTH($B11))*ISNUMBER('BOM Additions'!$E$3:$E$53)*1) | D11: =SUMPRODUCT((YEAR('BOM Additions'!$E$3:$E$53)=YEAR($B11))*(MONTH('BOM Additions'!$E$3:$E$53)=MONTH($B11))*ISNUMBER('BOM Additions'!$E$3:$E$53)*('BOM Additions'!$K$3:$K$53)) | E11: =IF(C11=0,"",D11/C11) | F11: =F10+D11
A12: Oct-26 | B12: 46296 | C12: =SUMPRODUCT((YEAR('BOM Additions'!$E$3:$E$53)=YEAR($B12))*(MONTH('BOM Additions'!$E$3:$E$53)=MONTH($B12))*ISNUMBER('BOM Additions'!$E$3:$E$53)*1) | D12: =SUMPRODUCT((YEAR('BOM Additions'!$E$3:$E$53)=YEAR($B12))*(MONTH('BOM Additions'!$E$3:$E$53)=MONTH($B12))*ISNUMBER('BOM Additions'!$E$3:$E$53)*('BOM Additions'!$K$3:$K$53)) | E12: =IF(C12=0,"",D12/C12) | F12: =F11+D12
A13: Nov-26 | B13: 46327 | C13: =SUMPRODUCT((YEAR('BOM Additions'!$E$3:$E$53)=YEAR($B13))*(MONTH('BOM Additions'!$E$3:$E$53)=MONTH($B13))*ISNUMBER('BOM Additions'!$E$3:$E$53)*1) | D13: =SUMPRODUCT((YEAR('BOM Additions'!$E$3:$E$53)=YEAR($B13))*(MONTH('BOM Additions'!$E$3:$E$53)=MONTH($B13))*ISNUMBER('BOM Additions'!$E$3:$E$53)*('BOM Additions'!$K$3:$K$53)) | E13: =IF(C13=0,"",D13/C13) | F13: =F12+D13
A14: Dec-26 | B14: 46357 | C14: =SUMPRODUCT((YEAR('BOM Additions'!$E$3:$E$53)=YEAR($B14))*(MONTH('BOM Additions'!$E$3:$E$53)=MONTH($B14))*ISNUMBER('BOM Additions'!$E$3:$E$53)*1) | D14: =SUMPRODUCT((YEAR('BOM Additions'!$E$3:$E$53)=YEAR($B14))*(MONTH('BOM Additions'!$E$3:$E$53)=MONTH($B14))*ISNUMBER('BOM Additions'!$E$3:$E$53)*('BOM Additions'!$K$3:$K$53)) | E14: =IF(C14=0,"",D14/C14) | F14: =F13+D14
A15: Jan-27 | B15: 46388 | C15: =SUMPRODUCT((YEAR('BOM Additions'!$E$3:$E$53)=YEAR($B15))*(MONTH('BOM Additions'!$E$3:$E$53)=MONTH($B15))*ISNUMBER('BOM Additions'!$E$3:$E$53)*1) | D15: =SUMPRODUCT((YEAR('BOM Additions'!$E$3:$E$53)=YEAR($B15))*(MONTH('BOM Additions'!$E$3:$E$53)=MONTH($B15))*ISNUMBER('BOM Additions'!$E$3:$E$53)*('BOM Additions'!$K$3:$K$53)) | E15: =IF(C15=0,"",D15/C15) | F15: =F14+D15
A16: TOTALS | C16: =SUM(C3:C15) | D16: =SUM(D3:D15)
